/work/tc062/tc062/manishav/.venv/diss/lib/python3.10/site-packages/transformers/utils/hub.py:127: FutureWarning: Using `TRANSFORMERS_CACHE` is deprecated and will be removed in v5 of Transformers. Use `HF_HOME` instead.
  warnings.warn(
/work/tc062/tc062/manishav/.venv/diss/lib/python3.10/site-packages/transformers/models/wav2vec2/processing_wav2vec2.py:55: FutureWarning: Loading a tokenizer inside Wav2Vec2Processor from a config that does not include a `tokenizer_class` attribute is deprecated and will be removed in v5. Please add `'tokenizer_class': 'Wav2Vec2CTCTokenizer'` attribute to either your `config.json` or `tokenizer_config.json` file to suppress this warning: 
  warnings.warn(
Traceback (most recent call last):
  File "/work/y07/shared/cirrus-software/miniconda3/22.11.1-1-py310-gpu/lib/python3.10/site-packages/urllib3/connection.py", line 174, in _new_conn
    conn = connection.create_connection(
  File "/work/y07/shared/cirrus-software/miniconda3/22.11.1-1-py310-gpu/lib/python3.10/site-packages/urllib3/util/connection.py", line 95, in create_connection
    raise err
  File "/work/y07/shared/cirrus-software/miniconda3/22.11.1-1-py310-gpu/lib/python3.10/site-packages/urllib3/util/connection.py", line 85, in create_connection
    sock.connect(sa)
OSError: [Errno 101] Network is unreachable

During handling of the above exception, another exception occurred:

Traceback (most recent call last):
  File "/work/y07/shared/cirrus-software/miniconda3/22.11.1-1-py310-gpu/lib/python3.10/site-packages/urllib3/connectionpool.py", line 703, in urlopen
    httplib_response = self._make_request(
  File "/work/y07/shared/cirrus-software/miniconda3/22.11.1-1-py310-gpu/lib/python3.10/site-packages/urllib3/connectionpool.py", line 386, in _make_request
    self._validate_conn(conn)
  File "/work/y07/shared/cirrus-software/miniconda3/22.11.1-1-py310-gpu/lib/python3.10/site-packages/urllib3/connectionpool.py", line 1042, in _validate_conn
    conn.connect()
  File "/work/y07/shared/cirrus-software/miniconda3/22.11.1-1-py310-gpu/lib/python3.10/site-packages/urllib3/connection.py", line 358, in connect
    self.sock = conn = self._new_conn()
  File "/work/y07/shared/cirrus-software/miniconda3/22.11.1-1-py310-gpu/lib/python3.10/site-packages/urllib3/connection.py", line 186, in _new_conn
    raise NewConnectionError(
urllib3.exceptions.NewConnectionError: <urllib3.connection.HTTPSConnection object at 0x14ccb34727d0>: Failed to establish a new connection: [Errno 101] Network is unreachable

During handling of the above exception, another exception occurred:

Traceback (most recent call last):
  File "/work/tc062/tc062/manishav/.venv/diss/lib/python3.10/site-packages/requests/adapters.py", line 667, in send
    resp = conn.urlopen(
  File "/work/y07/shared/cirrus-software/miniconda3/22.11.1-1-py310-gpu/lib/python3.10/site-packages/urllib3/connectionpool.py", line 787, in urlopen
    retries = retries.increment(
  File "/work/y07/shared/cirrus-software/miniconda3/22.11.1-1-py310-gpu/lib/python3.10/site-packages/urllib3/util/retry.py", line 592, in increment
    raise MaxRetryError(_pool, url, error or ResponseError(cause))
urllib3.exceptions.MaxRetryError: HTTPSConnectionPool(host='huggingface.co', port=443): Max retries exceeded with url: /facebook/hubert-large-ls960-ft/resolve/main/preprocessor_config.json (Caused by NewConnectionError('<urllib3.connection.HTTPSConnection object at 0x14ccb34727d0>: Failed to establish a new connection: [Errno 101] Network is unreachable'))

During handling of the above exception, another exception occurred:

Traceback (most recent call last):
  File "/work/tc062/tc062/manishav/.venv/diss/lib/python3.10/site-packages/huggingface_hub/file_download.py", line 1722, in _get_metadata_or_catch_error
    metadata = get_hf_file_metadata(url=url, proxies=proxies, timeout=etag_timeout, headers=headers)
  File "/work/tc062/tc062/manishav/.venv/diss/lib/python3.10/site-packages/huggingface_hub/utils/_validators.py", line 114, in _inner_fn
    return fn(*args, **kwargs)
  File "/work/tc062/tc062/manishav/.venv/diss/lib/python3.10/site-packages/huggingface_hub/file_download.py", line 1645, in get_hf_file_metadata
    r = _request_wrapper(
  File "/work/tc062/tc062/manishav/.venv/diss/lib/python3.10/site-packages/huggingface_hub/file_download.py", line 372, in _request_wrapper
    response = _request_wrapper(
  File "/work/tc062/tc062/manishav/.venv/diss/lib/python3.10/site-packages/huggingface_hub/file_download.py", line 395, in _request_wrapper
    response = get_session().request(method=method, url=url, **params)
  File "/work/tc062/tc062/manishav/.venv/diss/lib/python3.10/site-packages/requests/sessions.py", line 589, in request
    resp = self.send(prep, **send_kwargs)
  File "/work/tc062/tc062/manishav/.venv/diss/lib/python3.10/site-packages/requests/sessions.py", line 703, in send
    r = adapter.send(request, **kwargs)
  File "/work/tc062/tc062/manishav/.venv/diss/lib/python3.10/site-packages/huggingface_hub/utils/_http.py", line 66, in send
    return super().send(request, *args, **kwargs)
  File "/work/tc062/tc062/manishav/.venv/diss/lib/python3.10/site-packages/requests/adapters.py", line 700, in send
    raise ConnectionError(e, request=request)
requests.exceptions.ConnectionError: (MaxRetryError("HTTPSConnectionPool(host='huggingface.co', port=443): Max retries exceeded with url: /facebook/hubert-large-ls960-ft/resolve/main/preprocessor_config.json (Caused by NewConnectionError('<urllib3.connection.HTTPSConnection object at 0x14ccb34727d0>: Failed to establish a new connection: [Errno 101] Network is unreachable'))"), '(Request ID: 1d8703ce-8bf0-4a1e-846e-fb5bff595ce8)')

The above exception was the direct cause of the following exception:

Traceback (most recent call last):
  File "/work/tc062/tc062/manishav/.venv/diss/lib/python3.10/site-packages/transformers/utils/hub.py", line 402, in cached_file
    resolved_file = hf_hub_download(
  File "/work/tc062/tc062/manishav/.venv/diss/lib/python3.10/site-packages/huggingface_hub/utils/_validators.py", line 114, in _inner_fn
    return fn(*args, **kwargs)
  File "/work/tc062/tc062/manishav/.venv/diss/lib/python3.10/site-packages/huggingface_hub/file_download.py", line 1221, in hf_hub_download
    return _hf_hub_download_to_cache_dir(
  File "/work/tc062/tc062/manishav/.venv/diss/lib/python3.10/site-packages/huggingface_hub/file_download.py", line 1325, in _hf_hub_download_to_cache_dir
    _raise_on_head_call_error(head_call_error, force_download, local_files_only)
  File "/work/tc062/tc062/manishav/.venv/diss/lib/python3.10/site-packages/huggingface_hub/file_download.py", line 1826, in _raise_on_head_call_error
    raise LocalEntryNotFoundError(
huggingface_hub.utils._errors.LocalEntryNotFoundError: An error happened while trying to locate the file on the Hub and we cannot find the requested files in the local cache. Please check your connection and try again or make sure your Internet connection is on.

The above exception was the direct cause of the following exception:

Traceback (most recent call last):
  File "/work/tc062/tc062/manishav/.venv/diss/lib/python3.10/site-packages/transformers/models/wav2vec2/processing_wav2vec2.py", line 53, in from_pretrained
    return super().from_pretrained(pretrained_model_name_or_path, **kwargs)
  File "/work/tc062/tc062/manishav/.venv/diss/lib/python3.10/site-packages/transformers/processing_utils.py", line 836, in from_pretrained
    args = cls._get_arguments_from_pretrained(pretrained_model_name_or_path, **kwargs)
  File "/work/tc062/tc062/manishav/.venv/diss/lib/python3.10/site-packages/transformers/processing_utils.py", line 882, in _get_arguments_from_pretrained
    args.append(attribute_class.from_pretrained(pretrained_model_name_or_path, **kwargs))
  File "/work/tc062/tc062/manishav/.venv/diss/lib/python3.10/site-packages/transformers/feature_extraction_utils.py", line 373, in from_pretrained
    feature_extractor_dict, kwargs = cls.get_feature_extractor_dict(pretrained_model_name_or_path, **kwargs)
  File "/work/tc062/tc062/manishav/.venv/diss/lib/python3.10/site-packages/transformers/feature_extraction_utils.py", line 499, in get_feature_extractor_dict
    resolved_feature_extractor_file = cached_file(
  File "/work/tc062/tc062/manishav/.venv/diss/lib/python3.10/site-packages/transformers/utils/hub.py", line 445, in cached_file
    raise EnvironmentError(
OSError: We couldn't connect to 'https://huggingface.co' to load this file, couldn't find it in the cached files and it looks like facebook/hubert-large-ls960-ft is not the path to a directory containing a file named preprocessor_config.json.
Checkout your internet connection or see how to run the library in offline mode at 'https://huggingface.co/docs/transformers/installation#offline-mode'.

During handling of the above exception, another exception occurred:

Traceback (most recent call last):
  File "/work/y07/shared/cirrus-software/miniconda3/22.11.1-1-py310-gpu/lib/python3.10/site-packages/urllib3/connection.py", line 174, in _new_conn
    conn = connection.create_connection(
  File "/work/y07/shared/cirrus-software/miniconda3/22.11.1-1-py310-gpu/lib/python3.10/site-packages/urllib3/util/connection.py", line 95, in create_connection
    raise err
  File "/work/y07/shared/cirrus-software/miniconda3/22.11.1-1-py310-gpu/lib/python3.10/site-packages/urllib3/util/connection.py", line 85, in create_connection
    sock.connect(sa)
OSError: [Errno 101] Network is unreachable

During handling of the above exception, another exception occurred:

Traceback (most recent call last):
  File "/work/y07/shared/cirrus-software/miniconda3/22.11.1-1-py310-gpu/lib/python3.10/site-packages/urllib3/connectionpool.py", line 703, in urlopen
    httplib_response = self._make_request(
  File "/work/y07/shared/cirrus-software/miniconda3/22.11.1-1-py310-gpu/lib/python3.10/site-packages/urllib3/connectionpool.py", line 386, in _make_request
    self._validate_conn(conn)
  File "/work/y07/shared/cirrus-software/miniconda3/22.11.1-1-py310-gpu/lib/python3.10/site-packages/urllib3/connectionpool.py", line 1042, in _validate_conn
    conn.connect()
  File "/work/y07/shared/cirrus-software/miniconda3/22.11.1-1-py310-gpu/lib/python3.10/site-packages/urllib3/connection.py", line 358, in connect
    self.sock = conn = self._new_conn()
  File "/work/y07/shared/cirrus-software/miniconda3/22.11.1-1-py310-gpu/lib/python3.10/site-packages/urllib3/connection.py", line 186, in _new_conn
    raise NewConnectionError(
urllib3.exceptions.NewConnectionError: <urllib3.connection.HTTPSConnection object at 0x14ccb3472b60>: Failed to establish a new connection: [Errno 101] Network is unreachable

During handling of the above exception, another exception occurred:

Traceback (most recent call last):
  File "/work/tc062/tc062/manishav/.venv/diss/lib/python3.10/site-packages/requests/adapters.py", line 667, in send
    resp = conn.urlopen(
  File "/work/y07/shared/cirrus-software/miniconda3/22.11.1-1-py310-gpu/lib/python3.10/site-packages/urllib3/connectionpool.py", line 787, in urlopen
    retries = retries.increment(
  File "/work/y07/shared/cirrus-software/miniconda3/22.11.1-1-py310-gpu/lib/python3.10/site-packages/urllib3/util/retry.py", line 592, in increment
    raise MaxRetryError(_pool, url, error or ResponseError(cause))
urllib3.exceptions.MaxRetryError: HTTPSConnectionPool(host='huggingface.co', port=443): Max retries exceeded with url: /facebook/hubert-large-ls960-ft/resolve/main/preprocessor_config.json (Caused by NewConnectionError('<urllib3.connection.HTTPSConnection object at 0x14ccb3472b60>: Failed to establish a new connection: [Errno 101] Network is unreachable'))

During handling of the above exception, another exception occurred:

Traceback (most recent call last):
  File "/work/tc062/tc062/manishav/.venv/diss/lib/python3.10/site-packages/huggingface_hub/file_download.py", line 1722, in _get_metadata_or_catch_error
    metadata = get_hf_file_metadata(url=url, proxies=proxies, timeout=etag_timeout, headers=headers)
  File "/work/tc062/tc062/manishav/.venv/diss/lib/python3.10/site-packages/huggingface_hub/utils/_validators.py", line 114, in _inner_fn
    return fn(*args, **kwargs)
  File "/work/tc062/tc062/manishav/.venv/diss/lib/python3.10/site-packages/huggingface_hub/file_download.py", line 1645, in get_hf_file_metadata
    r = _request_wrapper(
  File "/work/tc062/tc062/manishav/.venv/diss/lib/python3.10/site-packages/huggingface_hub/file_download.py", line 372, in _request_wrapper
    response = _request_wrapper(
  File "/work/tc062/tc062/manishav/.venv/diss/lib/python3.10/site-packages/huggingface_hub/file_download.py", line 395, in _request_wrapper
    response = get_session().request(method=method, url=url, **params)
  File "/work/tc062/tc062/manishav/.venv/diss/lib/python3.10/site-packages/requests/sessions.py", line 589, in request
    resp = self.send(prep, **send_kwargs)
  File "/work/tc062/tc062/manishav/.venv/diss/lib/python3.10/site-packages/requests/sessions.py", line 703, in send
    r = adapter.send(request, **kwargs)
  File "/work/tc062/tc062/manishav/.venv/diss/lib/python3.10/site-packages/huggingface_hub/utils/_http.py", line 66, in send
    return super().send(request, *args, **kwargs)
  File "/work/tc062/tc062/manishav/.venv/diss/lib/python3.10/site-packages/requests/adapters.py", line 700, in send
    raise ConnectionError(e, request=request)
requests.exceptions.ConnectionError: (MaxRetryError("HTTPSConnectionPool(host='huggingface.co', port=443): Max retries exceeded with url: /facebook/hubert-large-ls960-ft/resolve/main/preprocessor_config.json (Caused by NewConnectionError('<urllib3.connection.HTTPSConnection object at 0x14ccb3472b60>: Failed to establish a new connection: [Errno 101] Network is unreachable'))"), '(Request ID: 4e52c672-4869-4ce5-822d-e0b4461c1a1f)')

The above exception was the direct cause of the following exception:

Traceback (most recent call last):
  File "/work/tc062/tc062/manishav/.venv/diss/lib/python3.10/site-packages/transformers/utils/hub.py", line 402, in cached_file
    resolved_file = hf_hub_download(
  File "/work/tc062/tc062/manishav/.venv/diss/lib/python3.10/site-packages/huggingface_hub/utils/_validators.py", line 114, in _inner_fn
    return fn(*args, **kwargs)
  File "/work/tc062/tc062/manishav/.venv/diss/lib/python3.10/site-packages/huggingface_hub/file_download.py", line 1221, in hf_hub_download
    return _hf_hub_download_to_cache_dir(
  File "/work/tc062/tc062/manishav/.venv/diss/lib/python3.10/site-packages/huggingface_hub/file_download.py", line 1325, in _hf_hub_download_to_cache_dir
    _raise_on_head_call_error(head_call_error, force_download, local_files_only)
  File "/work/tc062/tc062/manishav/.venv/diss/lib/python3.10/site-packages/huggingface_hub/file_download.py", line 1826, in _raise_on_head_call_error
    raise LocalEntryNotFoundError(
huggingface_hub.utils._errors.LocalEntryNotFoundError: An error happened while trying to locate the file on the Hub and we cannot find the requested files in the local cache. Please check your connection and try again or make sure your Internet connection is on.

The above exception was the direct cause of the following exception:

Traceback (most recent call last):
  File "/work/tc062/tc062/manishav/Diss/hubert_gs.py", line 71, in <module>
    processor = Wav2Vec2Processor.from_pretrained("facebook/hubert-large-ls960-ft")
  File "/work/tc062/tc062/manishav/.venv/diss/lib/python3.10/site-packages/transformers/models/wav2vec2/processing_wav2vec2.py", line 64, in from_pretrained
    feature_extractor = Wav2Vec2FeatureExtractor.from_pretrained(pretrained_model_name_or_path, **kwargs)
  File "/work/tc062/tc062/manishav/.venv/diss/lib/python3.10/site-packages/transformers/feature_extraction_utils.py", line 373, in from_pretrained
    feature_extractor_dict, kwargs = cls.get_feature_extractor_dict(pretrained_model_name_or_path, **kwargs)
  File "/work/tc062/tc062/manishav/.venv/diss/lib/python3.10/site-packages/transformers/feature_extraction_utils.py", line 499, in get_feature_extractor_dict
    resolved_feature_extractor_file = cached_file(
  File "/work/tc062/tc062/manishav/.venv/diss/lib/python3.10/site-packages/transformers/utils/hub.py", line 445, in cached_file
    raise EnvironmentError(
OSError: We couldn't connect to 'https://huggingface.co' to load this file, couldn't find it in the cached files and it looks like facebook/hubert-large-ls960-ft is not the path to a directory containing a file named preprocessor_config.json.
Checkout your internet connection or see how to run the library in offline mode at 'https://huggingface.co/docs/transformers/installation#offline-mode'.
srun: error: r2i5n6: task 0: Exited with exit code 1
srun: launch/slurm: _step_signal: Terminating StepId=5778100.0
