/work/tc062/tc062/manishav/.venv/diss/lib/python3.10/site-packages/transformers/utils/hub.py:127: FutureWarning: Using `TRANSFORMERS_CACHE` is deprecated and will be removed in v5 of Transformers. Use `HF_HOME` instead.
  warnings.warn(
/work/tc062/tc062/manishav/.venv/diss/lib/python3.10/site-packages/transformers/configuration_utils.py:364: UserWarning: Passing `gradient_checkpointing` to a config initialization is deprecated and will be removed in v5 Transformers. Using `model.gradient_checkpointing_enable()` instead, or if you are using the `Trainer` API, pass `gradient_checkpointing=True` in your `TrainingArguments`.
  warnings.warn(
Traceback (most recent call last):
  File "/work/y07/shared/cirrus-software/miniconda3/22.11.1-1-py310-gpu/lib/python3.10/site-packages/urllib3/connection.py", line 174, in _new_conn
    conn = connection.create_connection(
  File "/work/y07/shared/cirrus-software/miniconda3/22.11.1-1-py310-gpu/lib/python3.10/site-packages/urllib3/util/connection.py", line 95, in create_connection
    raise err
  File "/work/y07/shared/cirrus-software/miniconda3/22.11.1-1-py310-gpu/lib/python3.10/site-packages/urllib3/util/connection.py", line 85, in create_connection
    sock.connect(sa)
OSError: [Errno 101] Network is unreachable

During handling of the above exception, another exception occurred:

Traceback (most recent call last):
  File "/work/y07/shared/cirrus-software/miniconda3/22.11.1-1-py310-gpu/lib/python3.10/site-packages/urllib3/connectionpool.py", line 703, in urlopen
    httplib_response = self._make_request(
  File "/work/y07/shared/cirrus-software/miniconda3/22.11.1-1-py310-gpu/lib/python3.10/site-packages/urllib3/connectionpool.py", line 386, in _make_request
    self._validate_conn(conn)
  File "/work/y07/shared/cirrus-software/miniconda3/22.11.1-1-py310-gpu/lib/python3.10/site-packages/urllib3/connectionpool.py", line 1042, in _validate_conn
    conn.connect()
  File "/work/y07/shared/cirrus-software/miniconda3/22.11.1-1-py310-gpu/lib/python3.10/site-packages/urllib3/connection.py", line 358, in connect
    self.sock = conn = self._new_conn()
  File "/work/y07/shared/cirrus-software/miniconda3/22.11.1-1-py310-gpu/lib/python3.10/site-packages/urllib3/connection.py", line 186, in _new_conn
    raise NewConnectionError(
urllib3.exceptions.NewConnectionError: <urllib3.connection.HTTPSConnection object at 0x14e3ba6487c0>: Failed to establish a new connection: [Errno 101] Network is unreachable

During handling of the above exception, another exception occurred:

Traceback (most recent call last):
  File "/work/tc062/tc062/manishav/.venv/diss/lib/python3.10/site-packages/requests/adapters.py", line 667, in send
    resp = conn.urlopen(
  File "/work/y07/shared/cirrus-software/miniconda3/22.11.1-1-py310-gpu/lib/python3.10/site-packages/urllib3/connectionpool.py", line 787, in urlopen
    retries = retries.increment(
  File "/work/y07/shared/cirrus-software/miniconda3/22.11.1-1-py310-gpu/lib/python3.10/site-packages/urllib3/util/retry.py", line 592, in increment
    raise MaxRetryError(_pool, url, error or ResponseError(cause))
urllib3.exceptions.MaxRetryError: HTTPSConnectionPool(host='huggingface.co', port=443): Max retries exceeded with url: /ehcalabres/wav2vec2-lg-xlsr-en-speech-emotion-recognition/resolve/main/model.safetensors (Caused by NewConnectionError('<urllib3.connection.HTTPSConnection object at 0x14e3ba6487c0>: Failed to establish a new connection: [Errno 101] Network is unreachable'))

During handling of the above exception, another exception occurred:

Traceback (most recent call last):
  File "/work/tc062/tc062/manishav/Diss/gs-pyscripts/emofeatures.py", line 74, in <module>
    model = Wav2Vec2Model.from_pretrained("ehcalabres/wav2vec2-lg-xlsr-en-speech-emotion-recognition").to(device)
  File "/work/tc062/tc062/manishav/.venv/diss/lib/python3.10/site-packages/transformers/modeling_utils.py", line 3494, in from_pretrained
    if not has_file(pretrained_model_name_or_path, safe_weights_name, **has_file_kwargs):
  File "/work/tc062/tc062/manishav/.venv/diss/lib/python3.10/site-packages/transformers/utils/hub.py", line 655, in has_file
    response = get_session().head(
  File "/work/tc062/tc062/manishav/.venv/diss/lib/python3.10/site-packages/requests/sessions.py", line 624, in head
    return self.request("HEAD", url, **kwargs)
  File "/work/tc062/tc062/manishav/.venv/diss/lib/python3.10/site-packages/requests/sessions.py", line 589, in request
    resp = self.send(prep, **send_kwargs)
  File "/work/tc062/tc062/manishav/.venv/diss/lib/python3.10/site-packages/requests/sessions.py", line 703, in send
    r = adapter.send(request, **kwargs)
  File "/work/tc062/tc062/manishav/.venv/diss/lib/python3.10/site-packages/huggingface_hub/utils/_http.py", line 66, in send
    return super().send(request, *args, **kwargs)
  File "/work/tc062/tc062/manishav/.venv/diss/lib/python3.10/site-packages/requests/adapters.py", line 700, in send
    raise ConnectionError(e, request=request)
requests.exceptions.ConnectionError: (MaxRetryError("HTTPSConnectionPool(host='huggingface.co', port=443): Max retries exceeded with url: /ehcalabres/wav2vec2-lg-xlsr-en-speech-emotion-recognition/resolve/main/model.safetensors (Caused by NewConnectionError('<urllib3.connection.HTTPSConnection object at 0x14e3ba6487c0>: Failed to establish a new connection: [Errno 101] Network is unreachable'))"), '(Request ID: 53000757-6058-4a3d-afd3-f9bb19e0e84b)')
srun: error: r2i5n6: task 0: Exited with exit code 1
srun: launch/slurm: _step_signal: Terminating StepId=5813771.0
